<?xml version="1.0" encoding="UTF-8"?>
<testng-results skipped="0" failed="2" ignored="0" total="3" passed="1">
  <reporter-output>
  </reporter-output>
  <suite name="Default suite" duration-ms="7578" started-at="2017-08-17T06:16:15Z" finished-at="2017-08-17T06:16:22Z">
    <groups>
    </groups>
    <test name="Default test" duration-ms="7578" started-at="2017-08-17T06:16:15Z" finished-at="2017-08-17T06:16:22Z">
      <class name="Data_Driven.TestNG_Dataprovider">
        <test-method status="PASS" signature="OpenHotelApp()[pri:0, instance:Data_Driven.TestNG_Dataprovider@9629756]" name="OpenHotelApp" is-config="true" duration-ms="4548" started-at="2017-08-17T11:46:15Z" finished-at="2017-08-17T11:46:19Z">
          <reporter-output>
          </reporter-output>
        </test-method> <!-- OpenHotelApp -->
        <test-method status="FAIL" signature="main2(java.lang.String, java.lang.String)[pri:0, instance:Data_Driven.TestNG_Dataprovider@9629756]" name="main2" duration-ms="475" started-at="2017-08-17T11:46:19Z" data-provider="LoginCredentials" finished-at="2017-08-17T11:46:20Z">
          <params>
            <param index="0">
              <value>
                <![CDATA[Suraj123]]>
              </value>
            </param>
            <param index="1">
              <value>
                <![CDATA[Hex123]]>
              </value>
            </param>
          </params>
          <exception class="java.lang.AssertionError">
            <message>
              <![CDATA[expected [true] but found [false]]]>
            </message>
            <full-stacktrace>
              <![CDATA[java.lang.AssertionError: expected [true] but found [false]
	at org.testng.Assert.fail(Assert.java:93)
	at org.testng.Assert.failNotEquals(Assert.java:512)
	at org.testng.Assert.assertTrue(Assert.java:41)
	at org.testng.Assert.assertTrue(Assert.java:51)
	at Data_Driven.TestNG_Dataprovider.main2(TestNG_Dataprovider.java:64)
	at sun.reflect.NativeMethodAccessorImpl.invoke0(Native Method)
	at sun.reflect.NativeMethodAccessorImpl.invoke(Unknown Source)
	at sun.reflect.DelegatingMethodAccessorImpl.invoke(Unknown Source)
	at java.lang.reflect.Method.invoke(Unknown Source)
	at org.testng.internal.MethodInvocationHelper.invokeMethod(MethodInvocationHelper.java:108)
	at org.testng.internal.Invoker.invokeMethod(Invoker.java:661)
	at org.testng.internal.Invoker.invokeTestMethod(Invoker.java:869)
	at org.testng.internal.Invoker.invokeTestMethods(Invoker.java:1193)
	at org.testng.internal.TestMethodWorker.invokeTestMethods(TestMethodWorker.java:126)
	at org.testng.internal.TestMethodWorker.run(TestMethodWorker.java:109)
	at org.testng.TestRunner.privateRun(TestRunner.java:744)
	at org.testng.TestRunner.run(TestRunner.java:602)
	at org.testng.SuiteRunner.runTest(SuiteRunner.java:380)
	at org.testng.SuiteRunner.runSequentially(SuiteRunner.java:375)
	at org.testng.SuiteRunner.privateRun(SuiteRunner.java:340)
	at org.testng.SuiteRunner.run(SuiteRunner.java:289)
	at org.testng.SuiteRunnerWorker.runSuite(SuiteRunnerWorker.java:52)
	at org.testng.SuiteRunnerWorker.run(SuiteRunnerWorker.java:86)
	at org.testng.TestNG.runSuitesSequentially(TestNG.java:1301)
	at org.testng.TestNG.runSuitesLocally(TestNG.java:1226)
	at org.testng.TestNG.runSuites(TestNG.java:1144)
	at org.testng.TestNG.run(TestNG.java:1115)
	at org.testng.remote.AbstractRemoteTestNG.run(AbstractRemoteTestNG.java:132)
	at org.testng.remote.RemoteTestNG.initAndRun(RemoteTestNG.java:230)
	at org.testng.remote.RemoteTestNG.main(RemoteTestNG.java:76)
]]>
            </full-stacktrace>
          </exception> <!-- java.lang.AssertionError -->
          <reporter-output>
          </reporter-output>
        </test-method> <!-- main2 -->
        <test-method status="FAIL" signature="main2(java.lang.String, java.lang.String)[pri:0, instance:Data_Driven.TestNG_Dataprovider@9629756]" name="main2" duration-ms="408" started-at="2017-08-17T11:46:20Z" data-provider="LoginCredentials" finished-at="2017-08-17T11:46:20Z">
          <params>
            <param index="0">
              <value>
                <![CDATA[Suraj124]]>
              </value>
            </param>
            <param index="1">
              <value>
                <![CDATA[Hex124]]>
              </value>
            </param>
          </params>
          <exception class="java.lang.AssertionError">
            <message>
              <![CDATA[expected [true] but found [false]]]>
            </message>
            <full-stacktrace>
              <![CDATA[java.lang.AssertionError: expected [true] but found [false]
	at org.testng.Assert.fail(Assert.java:93)
	at org.testng.Assert.failNotEquals(Assert.java:512)
	at org.testng.Assert.assertTrue(Assert.java:41)
	at org.testng.Assert.assertTrue(Assert.java:51)
	at Data_Driven.TestNG_Dataprovider.main2(TestNG_Dataprovider.java:64)
	at sun.reflect.NativeMethodAccessorImpl.invoke0(Native Method)
	at sun.reflect.NativeMethodAccessorImpl.invoke(Unknown Source)
	at sun.reflect.DelegatingMethodAccessorImpl.invoke(Unknown Source)
	at java.lang.reflect.Method.invoke(Unknown Source)
	at org.testng.internal.MethodInvocationHelper.invokeMethod(MethodInvocationHelper.java:108)
	at org.testng.internal.Invoker.invokeMethod(Invoker.java:661)
	at org.testng.internal.Invoker.invokeTestMethod(Invoker.java:869)
	at org.testng.internal.Invoker.invokeTestMethods(Invoker.java:1193)
	at org.testng.internal.TestMethodWorker.invokeTestMethods(TestMethodWorker.java:126)
	at org.testng.internal.TestMethodWorker.run(TestMethodWorker.java:109)
	at org.testng.TestRunner.privateRun(TestRunner.java:744)
	at org.testng.TestRunner.run(TestRunner.java:602)
	at org.testng.SuiteRunner.runTest(SuiteRunner.java:380)
	at org.testng.SuiteRunner.runSequentially(SuiteRunner.java:375)
	at org.testng.SuiteRunner.privateRun(SuiteRunner.java:340)
	at org.testng.SuiteRunner.run(SuiteRunner.java:289)
	at org.testng.SuiteRunnerWorker.runSuite(SuiteRunnerWorker.java:52)
	at org.testng.SuiteRunnerWorker.run(SuiteRunnerWorker.java:86)
	at org.testng.TestNG.runSuitesSequentially(TestNG.java:1301)
	at org.testng.TestNG.runSuitesLocally(TestNG.java:1226)
	at org.testng.TestNG.runSuites(TestNG.java:1144)
	at org.testng.TestNG.run(TestNG.java:1115)
	at org.testng.remote.AbstractRemoteTestNG.run(AbstractRemoteTestNG.java:132)
	at org.testng.remote.RemoteTestNG.initAndRun(RemoteTestNG.java:230)
	at org.testng.remote.RemoteTestNG.main(RemoteTestNG.java:76)
]]>
            </full-stacktrace>
          </exception> <!-- java.lang.AssertionError -->
          <reporter-output>
          </reporter-output>
        </test-method> <!-- main2 -->
        <test-method status="PASS" signature="main2(java.lang.String, java.lang.String)[pri:0, instance:Data_Driven.TestNG_Dataprovider@9629756]" name="main2" duration-ms="2110" started-at="2017-08-17T11:46:20Z" data-provider="LoginCredentials" finished-at="2017-08-17T11:46:22Z">
          <params>
            <param index="0">
              <value>
                <![CDATA[Suraj2017]]>
              </value>
            </param>
            <param index="1">
              <value>
                <![CDATA[Dravid@2017]]>
              </value>
            </param>
          </params>
          <reporter-output>
          </reporter-output>
        </test-method> <!-- main2 -->
      </class> <!-- Data_Driven.TestNG_Dataprovider -->
    </test> <!-- Default test -->
  </suite> <!-- Default suite -->
</testng-results>
